2017-04-03 16:55:54,604 chat_bot.py[line:147] ERROR HTTPConnectionPool(host='192.168.212.128', port=4235): Max retries exceeded with url: /8044215:M69txLwWVwBmA9hxX5q328m8/getUpdates (Caused by NewConnectionError('<requests.packages.urllib3.connection.HTTPConnection object at 0x10ee13510>: Failed to establish a new connection: [Errno 61] Connection refused',))
2017-04-03 16:56:29,116 chat_bot.py[line:147] ERROR HTTPConnectionPool(host='192.168.212.128', port=4235): Max retries exceeded with url: /8044215:M69txLwWVwBmA9hxX5q328m8/getUpdates (Caused by NewConnectionError('<requests.packages.urllib3.connection.HTTPConnection object at 0x10bfa4510>: Failed to establish a new connection: [Errno 61] Connection refused',))
